2020-02-19 11:40:31,910 ERROR: Exception on /export_posts [GET] [in /home/kiryl/dev/edupurposes/flask-tutorial/env/lib/python3.6/site-packages/flask/app.py:1891]
Traceback (most recent call last):
  File "/home/kiryl/dev/edupurposes/flask-tutorial/env/lib/python3.6/site-packages/flask/app.py", line 2446, in wsgi_app
    response = self.full_dispatch_request()
  File "/home/kiryl/dev/edupurposes/flask-tutorial/env/lib/python3.6/site-packages/flask/app.py", line 1951, in full_dispatch_request
    rv = self.handle_user_exception(e)
  File "/home/kiryl/dev/edupurposes/flask-tutorial/env/lib/python3.6/site-packages/flask/app.py", line 1820, in handle_user_exception
    reraise(exc_type, exc_value, tb)
  File "/home/kiryl/dev/edupurposes/flask-tutorial/env/lib/python3.6/site-packages/flask/_compat.py", line 39, in reraise
    raise value
  File "/home/kiryl/dev/edupurposes/flask-tutorial/env/lib/python3.6/site-packages/flask/app.py", line 1949, in full_dispatch_request
    rv = self.dispatch_request()
  File "/home/kiryl/dev/edupurposes/flask-tutorial/env/lib/python3.6/site-packages/flask/app.py", line 1935, in dispatch_request
    return self.view_functions[rule.endpoint](**req.view_args)
  File "/home/kiryl/dev/edupurposes/flask-tutorial/env/lib/python3.6/site-packages/flask_login/utils.py", line 272, in decorated_view
    return func(*args, **kwargs)
  File "/home/kiryl/dev/edupurposes/flask-tutorial/app/main/routes.py", line 197, in export_posts
    current_user.launch_task('export_posts', 'Exporting posts...')
  File "/home/kiryl/dev/edupurposes/flask-tutorial/app/models.py", line 162, in launch_task
    db.session.add()
  File "/home/kiryl/dev/edupurposes/flask-tutorial/env/lib/python3.6/site-packages/sqlalchemy/orm/scoping.py", line 162, in do
    return getattr(self.registry(), name)(*args, **kwargs)
TypeError: add() missing 1 required positional argument: 'instance'
2020-02-19 11:40:43,374 ERROR: Exception on /notifications [GET] [in /home/kiryl/dev/edupurposes/flask-tutorial/env/lib/python3.6/site-packages/flask/app.py:1891]
Traceback (most recent call last):
  File "/home/kiryl/dev/edupurposes/flask-tutorial/env/lib/python3.6/site-packages/flask/app.py", line 2446, in wsgi_app
    response = self.full_dispatch_request()
  File "/home/kiryl/dev/edupurposes/flask-tutorial/env/lib/python3.6/site-packages/flask/app.py", line 1951, in full_dispatch_request
    rv = self.handle_user_exception(e)
  File "/home/kiryl/dev/edupurposes/flask-tutorial/env/lib/python3.6/site-packages/flask/app.py", line 1820, in handle_user_exception
    reraise(exc_type, exc_value, tb)
  File "/home/kiryl/dev/edupurposes/flask-tutorial/env/lib/python3.6/site-packages/flask/_compat.py", line 39, in reraise
    raise value
  File "/home/kiryl/dev/edupurposes/flask-tutorial/env/lib/python3.6/site-packages/flask/app.py", line 1949, in full_dispatch_request
    rv = self.dispatch_request()
  File "/home/kiryl/dev/edupurposes/flask-tutorial/env/lib/python3.6/site-packages/flask/app.py", line 1935, in dispatch_request
    return self.view_functions[rule.endpoint](**req.view_args)
  File "/home/kiryl/dev/edupurposes/flask-tutorial/env/lib/python3.6/site-packages/flask_login/utils.py", line 272, in decorated_view
    return func(*args, **kwargs)
  File "/home/kiryl/dev/edupurposes/flask-tutorial/app/main/routes.py", line 181, in notifications
    notifications = current_user.notifications.filter(Notification.timestamp > since) \
NameError: name 'Notification' is not defined
2020-02-19 11:40:53,389 ERROR: Exception on /notifications [GET] [in /home/kiryl/dev/edupurposes/flask-tutorial/env/lib/python3.6/site-packages/flask/app.py:1891]
Traceback (most recent call last):
  File "/home/kiryl/dev/edupurposes/flask-tutorial/env/lib/python3.6/site-packages/flask/app.py", line 2446, in wsgi_app
    response = self.full_dispatch_request()
  File "/home/kiryl/dev/edupurposes/flask-tutorial/env/lib/python3.6/site-packages/flask/app.py", line 1951, in full_dispatch_request
    rv = self.handle_user_exception(e)
  File "/home/kiryl/dev/edupurposes/flask-tutorial/env/lib/python3.6/site-packages/flask/app.py", line 1820, in handle_user_exception
    reraise(exc_type, exc_value, tb)
  File "/home/kiryl/dev/edupurposes/flask-tutorial/env/lib/python3.6/site-packages/flask/_compat.py", line 39, in reraise
    raise value
  File "/home/kiryl/dev/edupurposes/flask-tutorial/env/lib/python3.6/site-packages/flask/app.py", line 1949, in full_dispatch_request
    rv = self.dispatch_request()
  File "/home/kiryl/dev/edupurposes/flask-tutorial/env/lib/python3.6/site-packages/flask/app.py", line 1935, in dispatch_request
    return self.view_functions[rule.endpoint](**req.view_args)
  File "/home/kiryl/dev/edupurposes/flask-tutorial/env/lib/python3.6/site-packages/flask_login/utils.py", line 272, in decorated_view
    return func(*args, **kwargs)
  File "/home/kiryl/dev/edupurposes/flask-tutorial/app/main/routes.py", line 181, in notifications
    notifications = current_user.notifications.filter(Notification.timestamp > since) \
NameError: name 'Notification' is not defined
2020-02-19 11:41:02,246 INFO: Microblog startup [in /home/kiryl/dev/edupurposes/flask-tutorial/app/__init__.py:83]
2020-02-19 11:41:07,490 INFO: Microblog startup [in ./app/__init__.py:83]
2020-02-19 11:41:07,207 ERROR: Exception on /export_posts [GET] [in /home/kiryl/dev/edupurposes/flask-tutorial/env/lib/python3.6/site-packages/flask/app.py:1891]
Traceback (most recent call last):
  File "/home/kiryl/dev/edupurposes/flask-tutorial/env/lib/python3.6/site-packages/flask/app.py", line 2446, in wsgi_app
    response = self.full_dispatch_request()
  File "/home/kiryl/dev/edupurposes/flask-tutorial/env/lib/python3.6/site-packages/flask/app.py", line 1951, in full_dispatch_request
    rv = self.handle_user_exception(e)
  File "/home/kiryl/dev/edupurposes/flask-tutorial/env/lib/python3.6/site-packages/flask/app.py", line 1820, in handle_user_exception
    reraise(exc_type, exc_value, tb)
  File "/home/kiryl/dev/edupurposes/flask-tutorial/env/lib/python3.6/site-packages/flask/_compat.py", line 39, in reraise
    raise value
  File "/home/kiryl/dev/edupurposes/flask-tutorial/env/lib/python3.6/site-packages/flask/app.py", line 1949, in full_dispatch_request
    rv = self.dispatch_request()
  File "/home/kiryl/dev/edupurposes/flask-tutorial/env/lib/python3.6/site-packages/flask/app.py", line 1935, in dispatch_request
    return self.view_functions[rule.endpoint](**req.view_args)
  File "/home/kiryl/dev/edupurposes/flask-tutorial/env/lib/python3.6/site-packages/flask_login/utils.py", line 272, in decorated_view
    return func(*args, **kwargs)
  File "/home/kiryl/dev/edupurposes/flask-tutorial/app/main/routes.py", line 197, in export_posts
    current_user.launch_task('export_posts', 'Exporting posts...')
  File "/home/kiryl/dev/edupurposes/flask-tutorial/app/models.py", line 162, in launch_task
    db.session.add()
  File "/home/kiryl/dev/edupurposes/flask-tutorial/env/lib/python3.6/site-packages/sqlalchemy/orm/scoping.py", line 162, in do
    return getattr(self.registry(), name)(*args, **kwargs)
TypeError: add() missing 1 required positional argument: 'instance'
2020-02-19 11:41:36,618 INFO: Microblog startup [in /home/kiryl/dev/edupurposes/flask-tutorial/app/__init__.py:83]
2020-02-19 11:41:40,414 INFO: Microblog startup [in ./app/__init__.py:83]
2020-02-19 11:43:03,363 INFO: Microblog startup [in /home/kiryl/dev/edupurposes/flask-tutorial/app/__init__.py:83]
2020-02-19 11:43:10,097 INFO: Microblog startup [in ./app/__init__.py:83]
2020-02-19 11:43:30,249 ERROR: Unhandled exception [in ./app/tasks.py:61]
Traceback (most recent call last):
  File "/home/kiryl/dev/edupurposes/flask-tutorial/env/lib/python3.6/site-packages/flask_mail.py", line 492, in send
    message.send(connection)
  File "/home/kiryl/dev/edupurposes/flask-tutorial/env/lib/python3.6/site-packages/flask_mail.py", line 427, in send
    connection.send(self)
  File "/home/kiryl/dev/edupurposes/flask-tutorial/env/lib/python3.6/site-packages/flask_mail.py", line 192, in send
    message.rcpt_options)
  File "/usr/lib/python3.6/smtplib.py", line 852, in sendmail
    self.ehlo_or_helo_if_needed()
  File "/usr/lib/python3.6/smtplib.py", line 600, in ehlo_or_helo_if_needed
    if not (200 <= self.ehlo()[0] <= 299):
  File "/usr/lib/python3.6/smtplib.py", line 440, in ehlo
    self.putcmd(self.ehlo_msg, name or self.local_hostname)
  File "/usr/lib/python3.6/smtplib.py", line 367, in putcmd
    self.send(str)
  File "/usr/lib/python3.6/smtplib.py", line 359, in send
    raise SMTPServerDisconnected('please run connect() first')
smtplib.SMTPServerDisconnected: please run connect() first

During handling of the above exception, another exception occurred:

Traceback (most recent call last):
  File "./app/tasks.py", line 58, in export_posts
    attachments=[('posts.json', 'application/json', json.dumps({'posts': data}))], sync=True)
  File "./app/email.py", line 20, in send_email
    mail.send(msg)
  File "/home/kiryl/dev/edupurposes/flask-tutorial/env/lib/python3.6/site-packages/flask_mail.py", line 492, in send
    message.send(connection)
  File "/home/kiryl/dev/edupurposes/flask-tutorial/env/lib/python3.6/site-packages/flask_mail.py", line 152, in __exit__
    self.host.quit()
  File "/usr/lib/python3.6/smtplib.py", line 984, in quit
    res = self.docmd("quit")
  File "/usr/lib/python3.6/smtplib.py", line 420, in docmd
    self.putcmd(cmd, args)
  File "/usr/lib/python3.6/smtplib.py", line 367, in putcmd
    self.send(str)
  File "/usr/lib/python3.6/smtplib.py", line 359, in send
    raise SMTPServerDisconnected('please run connect() first')
smtplib.SMTPServerDisconnected: please run connect() first
2020-02-19 11:45:53,053 INFO: Microblog startup [in ./app/__init__.py:83]
